Workbook

Sheet Overview
B2: Toss Confirmation Tracking
B3: Super Selector — matches.toss_checked_at vs matches.start_time, pulled from Supabase project gepltclaeczgtruvekci
B5: What this tracks
B6: Every match row's toss_checked_at is the timestamp the check-toss Edge Function last touched it. That value only freezes (stops updating) once toss_status flips to 'confirmed' — so for a confirmed match, toss_checked_at IS the capture time. This workbook lines that capture time up against the match's own start_time so you can see, per match and per day, how far before (or after) kickoff the toss actually got recorded. Negative minutes on the 'Capture vs Start' column = captured before start (the system's intent — check-toss opens a 20-minute pre-match window and is designed to flag a delay once no toss has appeared by 10 minutes before start).
B12: Key finding
B13: Of 118 matches in the database, only 5 have ever had a toss actually captured — and all 5 are the most recent CPL 2026 matches (Aug 19-22, 2026). Every earlier match — 85 completed matches spanning Major League Cricket, IPL 2026, CPL 2026 (Matches 1-9), and the T20 Women's World Cup — shows no toss capture at all, i.e. check-toss never ran successfully against them.
B18: This matches a note already left in migrations/migration_v56_check_toss_cron.sql (dated 2026-08-18): the pg_cron job's Authorization key had gone stale from the moment the job was first written, silently 401'ing every single run — so check-toss never actually executed until that key was fixed, right around 2026-08-18/19. The data lines up exactly: nothing was ever captured before that, and the first matches to fall inside the check-toss window afterward all show activity.
B23: Since the fix
B24: Match 10 (CPL 2026) | C24: Started 2026-08-19 00:00 UTC — flagged delay_flagged right at start_time; no toss confirmed by either source.
B25: Match 11 (CPL 2026) | C25: Started 2026-08-19 23:00 UTC — confirmed 14 min BEFORE start (cricketaddictor). On target.
B26: Match 12 (CPL 2026) | C26: Started 2026-08-20 23:00 UTC — confirmed 7 min BEFORE start (cricketaddictor). On target.
B27: Match 13 (CPL 2026) | C27: Started 2026-08-21 23:00 UTC — confirmed 6 min BEFORE start (cricketaddictor). On target — 3rd confirmation in a row since the fix.
B28: Match 14 (CPL 2026) | C28: Started 2026-08-22 23:00 UTC — confirmed 10 min BEFORE start (cricketaddictor). First match checked under the widened 30-min window (deployed 2026-08-22); toss still landed ~10 min out, same as before — the wider window gives more polling passes, not an earlier source report.
B30: At a glance (live — recalculates as new daily pulls are appended to Match Detail)
B31: Total matches in table | D31: =COUNTA('Match Detail'!$J$2:$J$119) -> 118
B32: Matches ever toss-checked | D32: =COUNTIF('Match Detail'!$Q$2:$Q$119,"Yes") -> 5
B33: Toss confirmed | D33: =COUNTIF('Match Detail'!$J$2:$J$119,"confirmed") -> 4
B34: Delay flagged | D34: =COUNTIF('Match Detail'!$J$2:$J$119,"delay_flagged") -> 1
B35: Never checked | D35: =COUNTIF('Match Detail'!$Q$2:$Q$119,"No") -> 113
B36: Avg capture vs start, confirmed matches (min) | D36: =IFERROR(AVERAGEIFS('Match Detail'!$P$2:$P$119,'Match Detail'!$J$2:$J$119,"confirmed"),"n/a") -> -9.225
B38: How to extend this daily
B39: Re-run the same Supabase query against the matches table (id, tournament, match_number, teams, start_time, toss_status, toss_winner_name, toss_decision, toss_source, toss_checked_at) and append any new/updated rows to the Match Detail tab, keeping the same columns and formulas (drag column H:Q down for new rows). The Daily Summary tab will pick up new dates automatically once a row for that date exists on Match Detail with a matching Match Date (ET) value in column I. Ask me to pull a fresh export any day and I'll keep this workbook current.
B44: Data pulled: 2026-08-23 (America/New_York). Source: Supabase project gepltclaeczgtruvekci, table "matches".

Sheet Match Detail
A1: Tournament | B1: Match # | C1: Match Type | D1: Home Team | E1: Away Team | F1: Match Status | G1: Start Time (UTC) | H1: Start Time (ET) | I1: Match Date (ET) | J1: Toss Status | K1: Toss Winner | L1: Toss Decision | M1: Toss Source | N1: Toss Captured At (UTC) | O1: Toss Captured At (ET) | P1: Capture vs Start (min) | Q1: Ever Checked?
A2: IPL 2026 | B2: 63 | D2: Chennai Super Kings | E2: Sunrisers Hyderabad | F2: completed | G2: 46160.583 | H2: =G2-TIME(4,0,0) -> 46160.417 | I2: =INT(H2) -> 46160 | J2: pending | O2: =IF(N2="","",N2-TIME(4,0,0)) | P2: =IF(N2="","",ROUND((N2-G2)*1440,1)) | Q2: =IF(N2="","No","Yes") -> No
A3: IPL 2026 | B3: 64 | D3: Lucknow Super Giants | E3: Rajasthan Royals | F3: completed | G3: 46161.583 | H3: =G3-TIME(4,0,0) -> 46161.417 | I3: =INT(H3) -> 46161 | J3: pending | O3: =IF(N3="","",N3-TIME(4,0,0)) | P3: =IF(N3="","",ROUND((N3-G3)*1440,1)) | Q3: =IF(N3="","No","Yes") -> No
A4: IPL 2026 | B4: 65 | D4: Kolkata Knight Riders | E4: Mumbai Indians | F4: completed | G4: 46162.583 | H4: =G4-TIME(4,0,0) -> 46162.417 | I4: =INT(H4) -> 46162 | J4: pending | O4: =IF(N4="","",N4-TIME(4,0,0)) | P4: =IF(N4="","",ROUND((N4-G4)*1440,1)) | Q4: =IF(N4="","No","Yes") -> No
A5: IPL 2026 | B5: 66 | D5: Chennai Super Kings | E5: Gujarat Titans | F5: completed | G5: 46163.583 | H5: =G5-TIME(4,0,0) -> 46163.417 | I5: =INT(H5) -> 46163 | J5: pending | O5: =IF(N5="","",N5-TIME(4,0,0)) | P5: =IF(N5="","",ROUND((N5-G5)*1440,1)) | Q5: =IF(N5="","No","Yes") -> No
A6: IPL 2026 | B6: 67 | D6: Royal Challengers Bengaluru | E6: Sunrisers Hyderabad | F6: completed | G6: 46164.583 | H6: =G6-TIME(4,0,0) -> 46164.417 | I6: =INT(H6) -> 46164 | J6: pending | O6: =IF(N6="","",N6-TIME(4,0,0)) | P6: =IF(N6="","",ROUND((N6-G6)*1440,1)) | Q6: =IF(N6="","No","Yes") -> No
A7: IPL 2026 | B7: 68 | D7: Lucknow Super Giants | E7: Punjab Kings | F7: completed | G7: 46165.583 | H7: =G7-TIME(4,0,0) -> 46165.417 | I7: =INT(H7) -> 46165 | J7: pending | O7: =IF(N7="","",N7-TIME(4,0,0)) | P7: =IF(N7="","",ROUND((N7-G7)*1440,1)) | Q7: =IF(N7="","No","Yes") -> No
A8: IPL 2026 | B8: 69 | D8: Mumbai Indians | E8: Rajasthan Royals | F8: completed | G8: 46166.417 | H8: =G8-TIME(4,0,0) -> 46166.25 | I8: =INT(H8) -> 46166 | J8: pending | O8: =IF(N8="","",N8-TIME(4,0,0)) | P8: =IF(N8="","",ROUND((N8-G8)*1440,1)) | Q8: =IF(N8="","No","Yes") -> No
A9: IPL 2026 | B9: 70 | D9: Delhi Capitals | E9: Kolkata Knight Riders | F9: completed | G9: 46166.583 | H9: =G9-TIME(4,0,0) -> 46166.417 | I9: =INT(H9) -> 46166 | J9: pending | O9: =IF(N9="","",N9-TIME(4,0,0)) | P9: =IF(N9="","",ROUND((N9-G9)*1440,1)) | Q9: =IF(N9="","No","Yes") -> No
A10: IPL 2026 | B10: 71 | D10: Gujarat Titans | E10: Royal Challengers Bengaluru | F10: completed | G10: 46168.583 | H10: =G10-TIME(4,0,0) -> 46168.417 | I10: =INT(H10) -> 46168 | J10: pending | O10: =IF(N10="","",N10-TIME(4,0,0)) | P10: =IF(N10="","",ROUND((N10-G10)*1440,1)) | Q10: =IF(N10="","No","Yes") -> No
A11: IPL 2026 | B11: 72 | D11: Rajasthan Royals | E11: Sunrisers Hyderabad | F11: completed | G11: 46169.583 | H11: =G11-TIME(4,0,0) -> 46169.417 | I11: =INT(H11) -> 46169 | J11: pending | O11: =IF(N11="","",N11-TIME(4,0,0)) | P11: =IF(N11="","",ROUND((N11-G11)*1440,1)) | Q11: =IF(N11="","No","Yes") -> No
A12: IPL 2026 | B12: 73 | D12: Gujarat Titans | E12: Rajasthan Royals | F12: completed | G12: 46171.583 | H12: =G12-TIME(4,0,0) -> 46171.417 | I12: =INT(H12) -> 46171 | J12: pending | O12: =IF(N12="","",N12-TIME(4,0,0)) | P12: =IF(N12="","",ROUND((N12-G12)*1440,1)) | Q12: =IF(N12="","No","Yes") -> No
A13: IPL 2026 | B13: 74 | D13: Royal Challengers Bengaluru | E13: Gujarat Titans | F13: completed | G13: 46173.583 | H13: =G13-TIME(4,0,0) -> 46173.417 | I13: =INT(H13) -> 46173 | J13: pending | O13: =IF(N13="","",N13-TIME(4,0,0)) | P13: =IF(N13="","",ROUND((N13-G13)*1440,1)) | Q13: =IF(N13="","No","Yes") -> No
... A58: Major League Cricket | B58: 15 | D58: San Francisco Unicorns | E58: Washington Freedom | F58: completed | G58: 46202.062 | H58: =G58-TIME(4,0,0) -> 46201.896 | I58: =INT(H58) -> 46201 | J58: pending | O58: =IF(N58="","",N58-TIME(4,0,0)) | P58: =IF(N58="","",ROUND((N58-G58)*1440,1)) | Q58: =IF(N58="","No","Yes") -> No
A59: T20 Womens World Cup | D59: TBD | E59: TBD | F59: live | G59: 46203.562 | H59: =G59-TIME(4,0,0) -> 46203.396 | I59: =INT(H59) -> 46203 | J59: pending | O59: =IF(N59="","",N59-TIME(4,0,0)) | P59: =IF(N59="","",ROUND((N59-G59)*1440,1)) | Q59: =IF(N59="","No","Yes") -> No
A60: Major League Cricket | B60: 16 | D60: Los Angeles Knight Riders | E60: Washington Freedom | F60: completed | G60: 46205.062 | H60: =G60-TIME(4,0,0) -> 46204.896 | I60: =INT(H60) -> 46204 | J60: pending | O60: =IF(N60="","",N60-TIME(4,0,0)) | P60: =IF(N60="","",ROUND((N60-G60)*1440,1)) | Q60: =IF(N60="","No","Yes") -> No
A61: T20 Womens World Cup | D61: TBD | E61: TBD | F61: live | G61: 46205.729 | H61: =G61-TIME(4,0,0) -> 46205.562 | I61: =INT(H61) -> 46205 | J61: pending | O61: =IF(N61="","",N61-TIME(4,0,0)) | P61: =IF(N61="","",ROUND((N61-G61)*1440,1)) | Q61: =IF(N61="","No","Yes") -> No
A62: Major League Cricket | B62: 17 | D62: Mi New York | E62: Seattle Orcas | F62: completed | G62: 46206.062 | H62: =G62-TIME(4,0,0) -> 46205.896 | I62: =INT(H62) -> 46205 | J62: pending | O62: =IF(N62="","",N62-TIME(4,0,0)) | P62: =IF(N62="","",ROUND((N62-G62)*1440,1)) | Q62: =IF(N62="","No","Yes") -> No
A63: Major League Cricket | B63: 18 | D63: Los Angeles Knight Riders | E63: Texas Super Kings | F63: completed | G63: 46207.062 | H63: =G63-TIME(4,0,0) -> 46206.896 | I63: =INT(H63) -> 46206 | J63: pending | O63: =IF(N63="","",N63-TIME(4,0,0)) | P63: =IF(N63="","",ROUND((N63-G63)*1440,1)) | Q63: =IF(N63="","No","Yes") -> No
A64: Major League Cricket | B64: 19 | D64: San Francisco Unicorns | E64: Washington Freedom | F64: completed | G64: 46207.896 | H64: =G64-TIME(4,0,0) -> 46207.729 | I64: =INT(H64) -> 46207 | J64: pending | O64: =IF(N64="","",N64-TIME(4,0,0)) | P64: =IF(N64="","",ROUND((N64-G64)*1440,1)) | Q64: =IF(N64="","No","Yes") -> No
A65: Major League Cricket | B65: 20 | D65: Los Angeles Knight Riders | E65: Mi New York | F65: completed | G65: 46208.062 | H65: =G65-TIME(4,0,0) -> 46207.896 | I65: =INT(H65) -> 46207 | J65: pending | O65: =IF(N65="","",N65-TIME(4,0,0)) | P65: =IF(N65="","",ROUND((N65-G65)*1440,1)) | Q65: =IF(N65="","No","Yes") -> No
A66: T20 Womens World Cup | D66: TBD | E66: TBD | F66: live | G66: 46208.562 | H66: =G66-TIME(4,0,0) -> 46208.396 | I66: =INT(H66) -> 46208 | J66: pending | O66: =IF(N66="","",N66-TIME(4,0,0)) | P66: =IF(N66="","",ROUND((N66-G66)*1440,1)) | Q66: =IF(N66="","No","Yes") -> No
A67: Major League Cricket | B67: 21 | D67: Seattle Orcas | E67: Texas Super Kings | F67: completed | G67: 46208.896 | H67: =G67-TIME(4,0,0) -> 46208.729 | I67: =INT(H67) -> 46208 | J67: pending | O67: =IF(N67="","",N67-TIME(4,0,0)) | P67: =IF(N67="","",ROUND((N67-G67)*1440,1)) | Q67: =IF(N67="","No","Yes") -> No
A68: Major League Cricket | B68: 22 | D68: Mi New York | E68: San Francisco Unicorns | F68: completed | G68: 46209.062 | H68: =G68-TIME(4,0,0) -> 46208.896 | I68: =INT(H68) -> 46208 | J68: pending | O68: =IF(N68="","",N68-TIME(4,0,0)) | P68: =IF(N68="","",ROUND((N68-G68)*1440,1)) | Q68: =IF(N68="","No","Yes") -> No
A69: Major League Cricket | B69: 23 | D69: Mi New York | E69: San Francisco Unicorns | F69: completed | G69: 46212.021 | H69: =G69-TIME(4,0,0) -> 46211.854 | I69: =INT(H69) -> 46211 | J69: pending | O69: =IF(N69="","",N69-TIME(4,0,0)) | P69: =IF(N69="","",ROUND((N69-G69)*1440,1)) | Q69: =IF(N69="","No","Yes") -> No
A70: Major League Cricket | B70: 24 | D70: Los Angeles Knight Riders | E70: Washington Freedom | F70: completed | G70: 46213.021 | H70: =G70-TIME(4,0,0) -> 46212.854 | I70: =INT(H70) -> 46212 | J70: pending | O70: =IF(N70="","",N70-TIME(4,0,0)) | P70: =IF(N70="","",ROUND((N70-G70)*1440,1)) | Q70: =IF(N70="","No","Yes") -> No
A71: Major League Cricket | B71: 25 | D71: Mi New York | E71: Seattle Orcas | F71: completed | G71: 46213.854 | H71: =G71-TIME(4,0,0) -> 46213.688 | I71: =INT(H71) -> 46213 | J71: pending | O71: =IF(N71="","",N71-TIME(4,0,0)) | P71: =IF(N71="","",ROUND((N71-G71)*1440,1)) | Q71: =IF(N71="","No","Yes") -> No
A72: Major League Cricket | B72: 26 | D72: Los Angeles Knight Riders | E72: San Francisco Unicorns | F72: completed | G72: 46214.021 | H72: =G72-TIME(4,0,0) -> 46213.854 | I72: =INT(H72) -> 46213 | J72: pending | O72: =IF(N72="","",N72-TIME(4,0,0)) | P72: =IF(N72="","",ROUND((N72-G72)*1440,1)) | Q72: =IF(N72="","No","Yes") -> No
A73: Major League Cricket | B73: 27 | D73: Texas Super Kings | E73: Washington Freedom | F73: completed | G73: 46214.854 | H73: =G73-TIME(4,0,0) -> 46214.688 | I73: =INT(H73) -> 46214 | J73: pending | O73: =IF(N73="","",N73-TIME(4,0,0)) | P73: =IF(N73="","",ROUND((N73-G73)*1440,1)) | Q73: =IF(N73="","No","Yes") -> No
A74: Major League Cricket | B74: 28 | D74: San Francisco Unicorns | E74: Seattle Orcas | F74: completed | G74: 46215.021 | H74: =G74-TIME(4,0,0) -> 46214.854 | I74: =INT(H74) -> 46214 | J74: pending | O74: =IF(N74="","",N74-TIME(4,0,0)) | P74: =IF(N74="","",ROUND((N74-G74)*1440,1)) | Q74: =IF(N74="","No","Yes") -> No
A75: Major League Cricket | B75: 29 | D75: Mi New York | E75: Washington Freedom | F75: completed | G75: 46215.854 | H75: =G75-TIME(4,0,0) -> 46215.688 | I75: =INT(H75) -> 46215 | J75: pending | O75: =IF(N75="","",N75-TIME(4,0,0)) | P75: =IF(N75="","",ROUND((N75-G75)*1440,1)) | Q75: =IF(N75="","No","Yes") -> No
A76: Major League Cricket | B76: 30 | D76: Los Angeles Knight Riders | E76: Texas Super Kings | F76: completed | G76: 46216.021 | H76: =G76-TIME(4,0,0) -> 46215.854 | I76: =INT(H76) -> 46215 | J76: pending | O76: =IF(N76="","",N76-TIME(4,0,0)) | P76: =IF(N76="","",ROUND((N76-G76)*1440,1)) | Q76: =IF(N76="","No","Yes") -> No
A77: Major League Cricket | B77: 31 | C77: qualifier_1 | D77: Los Angeles Knight Riders | E77: San Francisco Unicorns | F77: completed | G77: 46218.896 | H77: =G77-TIME(4,0,0) -> 46218.729 | I77: =INT(H77) -> 46218 | J77: pending | O77: =IF(N77="","",N77-TIME(4,0,0)) | P77: =IF(N77="","",ROUND((N77-G77)*1440,1)) | Q77: =IF(N77="","No","Yes") -> No
A78: Major League Cricket | B78: 32 | C78: eliminator | D78: Mi New York | E78: Washington Freedom | F78: completed | G78: 46219.073 | H78: =G78-TIME(4,0,0) -> 46218.906 | I78: =INT(H78) -> 46218 | J78: pending | O78: =IF(N78="","",N78-TIME(4,0,0)) | P78: =IF(N78="","",ROUND((N78-G78)*1440,1)) | Q78: =IF(N78="","No","Yes") -> No
A79: Major League Cricket | B79: 33 | C79: qualifier_2 | D79: San Francisco Unicorns | E79: Washington Freedom | F79: completed | G79: 46220.062 | H79: =G79-TIME(4,0,0) -> 46219.896 | I79: =INT(H79) -> 46219 | J79: pending | O79: =IF(N79="","",N79-TIME(4,0,0)) | P79: =IF(N79="","",ROUND((N79-G79)*1440,1)) | Q79: =IF(N79="","No","Yes") -> No
A80: Major League Cricket | B80: 34 | C80: final | D80: Los Angeles Knight Riders | E80: Washington Freedom | F80: completed | G80: 46221.979 | H80: =G80-TIME(4,0,0) -> 46221.812 | I80: =INT(H80) -> 46221 | J80: pending | O80: =IF(N80="","",N80-TIME(4,0,0)) | P80: =IF(N80="","",ROUND((N80-G80)*1440,1)) | Q80: =IF(N80="","No","Yes") -> No
A81: Caribbean Premier League 2026 | B81: 1 | D81: Antigua and Barbuda Falcons | E81: Jamaica Kingsmen | F81: completed | G81: 46241.958 | H81: =G81-TIME(4,0,0) -> 46241.792 | I81: =INT(H81) -> 46241 | J81: pending | O81: =IF(N81="","",N81-TIME(4,0,0)) | P81: =IF(N81="","",ROUND((N81-G81)*1440,1)) | Q81: =IF(N81="","No","Yes") -> No
A82: Caribbean Premier League 2026 | B82: 2 | D82: St Kitts and Nevis Patriots | E82: Trinbago Knight Riders | F82: completed | G82: 46242.958 | H82: =G82-TIME(4,0,0) -> 46242.792 | I82: =INT(H82) -> 46242 | J82: pending | O82: =IF(N82="","",N82-TIME(4,0,0)) | P82: =IF(N82="","",ROUND((N82-G82)*1440,1)) | Q82: =IF(N82="","No","Yes") -> No
A83: Caribbean Premier League 2026 | B83: 3 | D83: Antigua and Barbuda Falcons | E83: Saint Lucia Kings | F83: completed | G83: 46243.958 | H83: =G83-TIME(4,0,0) -> 46243.792 | I83: =INT(H83) -> 46243 | J83: pending | O83: =IF(N83="","",N83-TIME(4,0,0)) | P83: =IF(N83="","",ROUND((N83-G83)*1440,1)) | Q83: =IF(N83="","No","Yes") -> No
A84: Caribbean Premier League 2026 | B84: 4 | D84: Barbados Tridents | E84: Jamaica Kingsmen | F84: completed | G84: 46245.917 | H84: =G84-TIME(4,0,0) -> 46245.75 | I84: =INT(H84) -> 46245 | J84: pending | O84: =IF(N84="","",N84-TIME(4,0,0)) | P84: =IF(N84="","",ROUND((N84-G84)*1440,1)) | Q84: =IF(N84="","No","Yes") -> No
...

Sheet Daily Summary
A1: Date (ET) | B1: Matches Scheduled | C1: Toss Checked | D1: Toss Confirmed | E1: Delay Flagged | F1: Never Checked | G1: Coverage % | H1: Avg Capture vs Start (min)
A2: 46160 | B2: =COUNTIFS('Match Detail'!$I$2:$I$119,$A2) -> 1 | C2: =COUNTIFS('Match Detail'!$I$2:$I$119,$A2,'Match Detail'!$Q$2:$Q$119,"Yes") -> 0 | D2: =COUNTIFS('Match Detail'!$I$2:$I$119,$A2,'Match Detail'!$J$2:$J$119,"confirmed") -> 0 | E2: =COUNTIFS('Match Detail'!$I$2:$I$119,$A2,'Match Detail'!$J$2:$J$119,"delay_flagged") -> 0 | F2: =B2-C2 -> 1 | G2: =IF(B2=0,0,C2/B2) -> 0 | H2: =IFERROR(AVERAGEIFS('Match Detail'!$P$2:$P$119,'Match Detail'!$I$2:$I$119,$A2,'Match Detail'!$J$2:$J$119,"confirmed"),"")
A3: 46161 | B3: =COUNTIFS('Match Detail'!$I$2:$I$119,$A3) -> 1 | C3: =COUNTIFS('Match Detail'!$I$2:$I$119,$A3,'Match Detail'!$Q$2:$Q$119,"Yes") -> 0 | D3: =COUNTIFS('Match Detail'!$I$2:$I$119,$A3,'Match Detail'!$J$2:$J$119,"confirmed") -> 0 | E3: =COUNTIFS('Match Detail'!$I$2:$I$119,$A3,'Match Detail'!$J$2:$J$119,"delay_flagged") -> 0 | F3: =B3-C3 -> 1 | G3: =IF(B3=0,0,C3/B3) -> 0 | H3: =IFERROR(AVERAGEIFS('Match Detail'!$P$2:$P$119,'Match Detail'!$I$2:$I$119,$A3,'Match Detail'!$J$2:$J$119,"confirmed"),"")
A4: 46162 | B4: =COUNTIFS('Match Detail'!$I$2:$I$119,$A4) -> 1 | C4: =COUNTIFS('Match Detail'!$I$2:$I$119,$A4,'Match Detail'!$Q$2:$Q$119,"Yes") -> 0 | D4: =COUNTIFS('Match Detail'!$I$2:$I$119,$A4,'Match Detail'!$J$2:$J$119,"confirmed") -> 0 | E4: =COUNTIFS('Match Detail'!$I$2:$I$119,$A4,'Match Detail'!$J$2:$J$119,"delay_flagged") -> 0 | F4: =B4-C4 -> 1 | G4: =IF(B4=0,0,C4/B4) -> 0 | H4: =IFERROR(AVERAGEIFS('Match Detail'!$P$2:$P$119,'Match Detail'!$I$2:$I$119,$A4,'Match Detail'!$J$2:$J$119,"confirmed"),"")
A5: 46163 | B5: =COUNTIFS('Match Detail'!$I$2:$I$119,$A5) -> 1 | C5: =COUNTIFS('Match Detail'!$I$2:$I$119,$A5,'Match Detail'!$Q$2:$Q$119,"Yes") -> 0 | D5: =COUNTIFS('Match Detail'!$I$2:$I$119,$A5,'Match Detail'!$J$2:$J$119,"confirmed") -> 0 | E5: =COUNTIFS('Match Detail'!$I$2:$I$119,$A5,'Match Detail'!$J$2:$J$119,"delay_flagged") -> 0 | F5: =B5-C5 -> 1 | G5: =IF(B5=0,0,C5/B5) -> 0 | H5: =IFERROR(AVERAGEIFS('Match Detail'!$P$2:$P$119,'Match Detail'!$I$2:$I$119,$A5,'Match Detail'!$J$2:$J$119,"confirmed"),"")
A6: 46164 | B6: =COUNTIFS('Match Detail'!$I$2:$I$119,$A6) -> 1 | C6: =COUNTIFS('Match Detail'!$I$2:$I$119,$A6,'Match Detail'!$Q$2:$Q$119,"Yes") -> 0 | D6: =COUNTIFS('Match Detail'!$I$2:$I$119,$A6,'Match Detail'!$J$2:$J$119,"confirmed") -> 0 | E6: =COUNTIFS('Match Detail'!$I$2:$I$119,$A6,'Match Detail'!$J$2:$J$119,"delay_flagged") -> 0 | F6: =B6-C6 -> 1 | G6: =IF(B6=0,0,C6/B6) -> 0 | H6: =IFERROR(AVERAGEIFS('Match Detail'!$P$2:$P$119,'Match Detail'!$I$2:$I$119,$A6,'Match Detail'!$J$2:$J$119,"confirmed"),"")
A7: 46165 | B7: =COUNTIFS('Match Detail'!$I$2:$I$119,$A7) -> 1 | C7: =COUNTIFS('Match Detail'!$I$2:$I$119,$A7,'Match Detail'!$Q$2:$Q$119,"Yes") -> 0 | D7: =COUNTIFS('Match Detail'!$I$2:$I$119,$A7,'Match Detail'!$J$2:$J$119,"confirmed") -> 0 | E7: =COUNTIFS('Match Detail'!$I$2:$I$119,$A7,'Match Detail'!$J$2:$J$119,"delay_flagged") -> 0 | F7: =B7-C7 -> 1 | G7: =IF(B7=0,0,C7/B7) -> 0 | H7: =IFERROR(AVERAGEIFS('Match Detail'!$P$2:$P$119,'Match Detail'!$I$2:$I$119,$A7,'Match Detail'!$J$2:$J$119,"confirmed"),"")
A8: 46166 | B8: =COUNTIFS('Match Detail'!$I$2:$I$119,$A8) -> 2 | C8: =COUNTIFS('Match Detail'!$I$2:$I$119,$A8,'Match Detail'!$Q$2:$Q$119,"Yes") -> 0 | D8: =COUNTIFS('Match Detail'!$I$2:$I$119,$A8,'Match Detail'!$J$2:$J$119,"confirmed") -> 0 | E8: =COUNTIFS('Match Detail'!$I$2:$I$119,$A8,'Match Detail'!$J$2:$J$119,"delay_flagged") -> 0 | F8: =B8-C8 -> 2 | G8: =IF(B8=0,0,C8/B8) -> 0 | H8: =IFERROR(AVERAGEIFS('Match Detail'!$P$2:$P$119,'Match Detail'!$I$2:$I$119,$A8,'Match Detail'!$J$2:$J$119,"confirmed"),"")
A9: 46168 | B9: =COUNTIFS('Match Detail'!$I$2:$I$119,$A9) -> 1 | C9: =COUNTIFS('Match Detail'!$I$2:$I$119,$A9,'Match Detail'!$Q$2:$Q$119,"Yes") -> 0 | D9: =COUNTIFS('Match Detail'!$I$2:$I$119,$A9,'Match Detail'!$J$2:$J$119,"confirmed") -> 0 | E9: =COUNTIFS('Match Detail'!$I$2:$I$119,$A9,'Match Detail'!$J$2:$J$119,"delay_flagged") -> 0 | F9: =B9-C9 -> 1 | G9: =IF(B9=0,0,C9/B9) -> 0 | H9: =IFERROR(AVERAGEIFS('Match Detail'!$P$2:$P$119,'Match Detail'!$I$2:$I$119,$A9,'Match Detail'!$J$2:$J$119,"confirmed"),"")
A10: 46169 | B10: =COUNTIFS('Match Detail'!$I$2:$I$119,$A10) -> 1 | C10: =COUNTIFS('Match Detail'!$I$2:$I$119,$A10,'Match Detail'!$Q$2:$Q$119,"Yes") -> 0 | D10: =COUNTIFS('Match Detail'!$I$2:$I$119,$A10,'Match Detail'!$J$2:$J$119,"confirmed") -> 0 | E10: =COUNTIFS('Match Detail'!$I$2:$I$119,$A10,'Match Detail'!$J$2:$J$119,"delay_flagged") -> 0 | F10: =B10-C10 -> 1 | G10: =IF(B10=0,0,C10/B10) -> 0 | H10: =IFERROR(AVERAGEIFS('Match Detail'!$P$2:$P$119,'Match Detail'!$I$2:$I$119,$A10,'Match Detail'!$J$2:$J$119,"confirmed"),"")
A11: 46171 | B11: =COUNTIFS('Match Detail'!$I$2:$I$119,$A11) -> 1 | C11: =COUNTIFS('Match Detail'!$I$2:$I$119,$A11,'Match Detail'!$Q$2:$Q$119,"Yes") -> 0 | D11: =COUNTIFS('Match Detail'!$I$2:$I$119,$A11,'Match Detail'!$J$2:$J$119,"confirmed") -> 0 | E11: =COUNTIFS('Match Detail'!$I$2:$I$119,$A11,'Match Detail'!$J$2:$J$119,"delay_flagged") -> 0 | F11: =B11-C11 -> 1 | G11: =IF(B11=0,0,C11/B11) -> 0 | H11: =IFERROR(AVERAGEIFS('Match Detail'!$P$2:$P$119,'Match Detail'!$I$2:$I$119,$A11,'Match Detail'!$J$2:$J$119,"confirmed"),"")
A12: 46173 | B12: =COUNTIFS('Match Detail'!$I$2:$I$119,$A12) -> 1 | C12: =COUNTIFS('Match Detail'!$I$2:$I$119,$A12,'Match Detail'!$Q$2:$Q$119,"Yes") -> 0 | D12: =COUNTIFS('Match Detail'!$I$2:$I$119,$A12,'Match Detail'!$J$2:$J$119,"confirmed") -> 0 | E12: =COUNTIFS('Match Detail'!$I$2:$I$119,$A12,'Match Detail'!$J$2:$J$119,"delay_flagged") -> 0 | F12: =B12-C12 -> 1 | G12: =IF(B12=0,0,C12/B12) -> 0 | H12: =IFERROR(AVERAGEIFS('Match Detail'!$P$2:$P$119,'Match Detail'!$I$2:$I$119,$A12,'Match Detail'!$J$2:$J$119,"confirmed"),"")
A13: 46185 | B13: =COUNTIFS('Match Detail'!$I$2:$I$119,$A13) -> 1 | C13: =COUNTIFS('Match Detail'!$I$2:$I$119,$A13,'Match Detail'!$Q$2:$Q$119,"Yes") -> 0 | D13: =COUNTIFS('Match Detail'!$I$2:$I$119,$A13,'Match Detail'!$J$2:$J$119,"confirmed") -> 0 | E13: =COUNTIFS('Match Detail'!$I$2:$I$119,$A13,'Match Detail'!$J$2:$J$119,"delay_flagged") -> 0 | F13: =B13-C13 -> 1 | G13: =IF(B13=0,0,C13/B13) -> 0 | H13: =IFERROR(AVERAGEIFS('Match Detail'!$P$2:$P$119,'Match Detail'!$I$2:$I$119,$A13,'Match Detail'!$J$2:$J$119,"confirmed"),"")
... A79: 46285 | B79: =COUNTIFS('Match Detail'!$I$2:$I$119,$A79) -> 1 | C79: =COUNTIFS('Match Detail'!$I$2:$I$119,$A79,'Match Detail'!$Q$2:$Q$119,"Yes") -> 0 | D79: =COUNTIFS('Match Detail'!$I$2:$I$119,$A79,'Match Detail'!$J$2:$J$119,"confirmed") -> 0 | E79: =COUNTIFS('Match Detail'!$I$2:$I$119,$A79,'Match Detail'!$J$2:$J$119,"delay_flagged") -> 0 | F79: =B79-C79 -> 1 | G79: =IF(B79=0,0,C79/B79) -> 0 | H79: =IFERROR(AVERAGEIFS('Match Detail'!$P$2:$P$119,'Match Detail'!$I$2:$I$119,$A79,'Match Detail'!$J$2:$J$119,"confirmed"),"")
